Workbook

Sheet Navigation Pane
B2: Click on a sheet name to navigate directly to that sheet.
B4: Financial Model Layout -
B5: Valuation
B6: Scenario Analysis
B7: Asumption Sheet
B8: Balance Sheet
B9: Income Statement
B10: Cash Flow Statement
B11: Revenue Model
B12: Cost Model
B13: Capex Schedule
B14: Depreciation & Finance Cost Schedule
... B19: Once on the sheet, click on the top-left cell (A1) of the sheet (i.e., the sheet name) to return to this page.

Sheet Valuation
A1: Valuation
A2: Figures in Lakhs ,expect otherwise stated
A3: Particular/Years | B3: Comments | C3: 2021-22 A | D3: 2022-23 A | E3: 2023-24 A | F3: 2024-25 A | G3: 2025-26 E | H3: 2026-27 E | I3: 2027-28 E | J3: 2028-29 E | K3: 2029-30 E
A4: DCF Method
A5: Cash flow from Operations | C5: =CFS!C31 -> 9442.52 | D5: =CFS!D31 -> 9343.03 | E5: =CFS!E31 -> 9324.54 | F5: =CFS!F31 -> 33119.56 | G5: =CFS!G31 -> 30438.285 | H5: =CFS!H31 -> 30188.747 | I5: =CFS!I31 -> 33273.052 | J5: =CFS!J31 -> 39151.891 | K5: =CFS!K31 -> 42967.403
A6: =CFS!A51 -> Interest paid | C6: =CFS!C51 -> -94.63 | D6: =CFS!D51 -> -62.22 | E6: =CFS!E51 -> -298.92 | F6: =CFS!F51 -> -88.23 | G6: =CFS!G51 -> -153.11296 | H6: =CFS!H51 -> -144.20856 | I6: =CFS!I51 -> -137.96847 | J6: =CFS!J51 -> -133.5955 | K6: =CFS!K51 -> -130.53098
A7: Cash flow from Investing | C7: =CFS!C41 -> -63029.27 | D7: =CFS!D41 -> -14814.25 | E7: =CFS!E41 -> 1659.42 | F7: =CFS!F41 -> -22060.2 | G7: =CFS!G41 -> -23469.615 | H7: =CFS!H41 -> -22587.572 | I7: =CFS!I41 -> -21107.614 | J7: =CFS!J41 -> 2397.1459 | K7: =CFS!K41 -> 5555.1186
A8: Net Borrowings | B8: Issue - Repayment | C8: =CFS!C46+CFS!C47 -> 0 | D8: =CFS!D46+CFS!D47 -> 0 | E8: =CFS!E46+CFS!E47 -> -140.06 | F8: =CFS!F46+CFS!F47 -> -165.02 | G8: =CFS!G46+CFS!G47 -> 0 | H8: =CFS!H46+CFS!H47 -> 0 | I8: =CFS!I46+CFS!I47 -> 0 | J8: =CFS!J46+CFS!J47 -> 0 | K8: =CFS!K46+CFS!K47 -> 0
A9: Free Cash flow to Equity | C9: =SUM(C5:C8) -> -53681.38 | D9: =SUM(D5:D8) -> -5533.44 | E9: =SUM(E5:E8) -> 10544.98 | F9: =SUM(F5:F8) -> 10806.11 | G9: =SUM(G5:G8) -> 6815.5567 | H9: =SUM(H5:H8) -> 7456.9666 | I9: =SUM(I5:I8) -> 12027.47 | J9: =SUM(J5:J8) -> 41415.442 | K9: =SUM(K5:K8) -> 48391.99
A11: Risk Free Rate | B11: ='Assumption Sheet'!B149 -> 0.0603
A12: Beta | B12: ='Assumption Sheet'!B150 -> 0.59
A13: Equity Risk Premium | B13: ='Assumption Sheet'!B151 -> 0.0708
A14: Cost of Equity | B14: =B11+(B12*B13) -> 0.102072
A16: Growth Rate at terminal year | B16: ='Assumption Sheet'!B152 -> 0.05
A18: Date | G18: 46112 | H18: 46477 | I18: 46843 | J18: 47208 | K18: 47573
A19: FCFE | G19: =G9 -> 6815.5567 | H19: =H9 -> 7456.9666 | I19: =I9 -> 12027.47 | J19: =J9 -> 41415.442 | K19: =K9 -> 48391.99
A20: Terminal Value | K20: =(K19*(1+B16))/(B14-B16) -> 975794.86
A21: Total Cash flow | G21: =SUM(G19:G20) -> 6815.5567 | H21: =SUM(H19:H20) -> 7456.9666 | I21: =SUM(I19:I20) -> 12027.47 | J21: =SUM(J19:J20) -> 41415.442 | K21: =SUM(K19:K20) -> 1024186.9
A23: Value of the Company | B23: =XNPV(B14,G21:K21,G18:K18) -> 748517.19
A24: Shares O/s | B24: 1928.09
A26: Value Per Share | B26: =B23/B24 -> 388.21693

Sheet Scenario Analysis 
A1: Scenario Analysis
A2: Figures in Lakhs ,expect otherwise stated
A3: Particular/Years | B3: Comments | C3: 2021-22 A | D3: 2022-23 A | E3: 2023-24 A | F3: 2024-25 A | G3: 2025-26 E | H3: 2026-27 E | I3: 2027-28 E | J3: 2028-29 E | K3: 2029-30 E
A5: =Valuation!A26 -> Value Per Share | B5: =Valuation!B26 -> 388.21693
A7: Y-o-Y Growth in Sale in Quantity of Products | B7: 2
A8: Best Scenario | C8: ='Assumption Sheet'!C8 -> - | D8: ='Assumption Sheet'!D8 -> 0.39900249 | E8: ='Assumption Sheet'!E8 -> 0.2228164 | F8: ='Assumption Sheet'!F8 -> -0.36734694 | G8: -0.05 | H8: -0.05 | I8: -0.05 | J8: -0.05 | K8: -0.05
A9: Base Scenario | B9: Mgmnt Guidance- Mgmnt will not focus much on this segment and rather focus on music segment | C9: ='Assumption Sheet'!C8 -> - | D9: ='Assumption Sheet'!D8 -> 0.39900249 | E9: ='Assumption Sheet'!E8 -> 0.2228164 | F9: ='Assumption Sheet'!F8 -> -0.36734694 | G9: -0.2 | H9: -0.2 | I9: -0.2 | J9: -0.2 | K9: -0.2
A10: Worst Scenario | C10: ='Assumption Sheet'!C8 -> - | D10: ='Assumption Sheet'!D8 -> 0.39900249 | E10: ='Assumption Sheet'!E8 -> 0.2228164 | F10: ='Assumption Sheet'!F8 -> -0.36734694 | G10: -0.4 | H10: -0.4 | I10: -0.4 | J10: -0.4 | K10: -0.4
A13: Y-o-Y Increase in Revenue per song of Songs After 2021 | B13: 2
A14: Best Scenario | C14: ='Assumption Sheet'!C22 -> 0 | D14: ='Assumption Sheet'!D22 -> 0 | E14: ='Assumption Sheet'!E22 -> -0.25654146 | F14: ='Assumption Sheet'!F22 -> 0.091999196 | G14: 0.2 | H14: 0.25 | I14: 0.15 | J14: 0.13 | K14: 0.14 | P14: 1
A15: Base Scenario | B15: Expicit- Agressive investment till FY 2027 | C15: ='Assumption Sheet'!C22 -> 0 | D15: ='Assumption Sheet'!D22 -> 0 | E15: ='Assumption Sheet'!E22 -> -0.25654146 | F15: ='Assumption Sheet'!F22 -> 0.091999196 | G15: 0.15 | H15: 0.2 | I15: 0.1 | J15: 0.08 | K15: 0.09 | P15: 2
A16: Worst Scenario | C16: ='Assumption Sheet'!C22 -> 0 | D16: ='Assumption Sheet'!D22 -> 0 | E16: ='Assumption Sheet'!E22 -> -0.25654146 | F16: ='Assumption Sheet'!F22 -> 0.091999196 | G16: 0.1 | H16: 0.15 | I16: 0.05 | J16: 0.03 | K16: 0.04 | P16: 3
A19: Y-o-Y Growth in music Segment | B19: 2
A20: Best Scenario | C20: ='Assumption Sheet'!C25 -> 0 | D20: ='Assumption Sheet'!D25 -> 0.15947794 | E20: ='Assumption Sheet'!E25 -> 0.1847445 | F20: ='Assumption Sheet'!F25 -> 0.21817235 | G20: 0.3 | H20: 0.3 | I20: 0.3 | J20: 0.3 | K20: 0.3
A21: Base Scenario | B21: Mgmnt Guidance | C21: ='Assumption Sheet'!C25 -> 0 | D21: ='Assumption Sheet'!D25 -> 0.15947794 | E21: ='Assumption Sheet'!E25 -> 0.1847445 | F21: ='Assumption Sheet'!F25 -> 0.21817235 | G21: 0.21 | H21: 0.21 | I21: 0.21 | J21: 0.21 | K21: 0.21
A22: Worst Scenario | C22: ='Assumption Sheet'!C25 -> 0 | D22: ='Assumption Sheet'!D25 -> 0.15947794 | E22: ='Assumption Sheet'!E25 -> 0.1847445 | F22: ='Assumption Sheet'!F25 -> 0.21817235 | G22: 0.15 | H22: 0.15 | I22: 0.15 | J22: 0.15 | K22: 0.15
A24: Y-o-Y Growth in Video Segment | B24: 3
A25: Best Scenario | C25: ='Assumption Sheet'!C28 -> - | D25: ='Assumption Sheet'!D28 -> 0.059298007 | E25: ='Assumption Sheet'!E28 -> 0.068260207 | F25: ='Assumption Sheet'!F28 -> 0.65688473 | G25: 0.4 | H25: 0.4 | I25: 0.4 | J25: 0.4 | K25: 0.4
A26: Base Scenario | B26: Mgmnt Guidance | C26: ='Assumption Sheet'!C28 -> - | D26: ='Assumption Sheet'!D28 -> 0.059298007 | E26: ='Assumption Sheet'!E28 -> 0.068260207 | F26: ='Assumption Sheet'!F28 -> 0.65688473 | G26: 0.25 | H26: 0.25 | I26: 0.25 | J26: 0.25 | K26: 0.25
A27: Worst Scenario | C27: ='Assumption Sheet'!C28 -> - | D27: ='Assumption Sheet'!D28 -> 0.059298007 | E27: ='Assumption Sheet'!E28 -> 0.068260207 | F27: ='Assumption Sheet'!F28 -> 0.65688473 | G27: 0.15 | H27: 0.15 | I27: 0.15 | J27: 0.15 | K27: 0.15
A30: Y-o-Y Growth in Events Segment | B30: 3
A31: Best Scenario | C31: 0 | D31: 0 | E31: -0.72543641 | F31: 20.220619 | G31: 0.4 | H31: 0.4 | I31: 0.4 | J31: 0.4 | K31: 0.4
A32: Base Scenario | C32: 0 | D32: 0 | E32: -0.72543641 | F32: 20.220619 | G32: 0.15 | H32: 0.15 | I32: 0.15 | J32: 0.15 | K32: 0.15
A33: Worst Scenario | C33: 0 | D33: 0 | E33: -0.72543641 | F33: 20.220619 | G33: -0.1 | H33: -0.1 | I33: -0.1 | J33: -0.1 | K33: -0.1
A35: Aquistion of Music | B35: 2
A36: Best Scenario | B36: Mgmnt Guidance - 1000 Cr. Investment between 2025 to 2027 and then increase in Intangible asset at inflation rate of 6%. Therefore, 827.81 Cr in next 2 years | C36: ='Assumption Sheet'!C97 -> 5209.07 | D36: ='Assumption Sheet'!D97 -> 7200.22 | E36: ='Assumption Sheet'!E97 -> 9882.27 | F36: ='Assumption Sheet'!F97 -> 17218.87 | G36: 41390.565 | H36: 41390.565 | I36: 7486.15 | J36: =I36*(1+6%) -> 7935.319 | K36: =J36*(1+6%) -> 8411.4381
A37: Base Scenario | B37: Out of 1000 Cr, 172.19 Cr is invested remaning 827.81Cr over 3 years | C37: ='Assumption Sheet'!C97 -> 5209.07 | D37: ='Assumption Sheet'!D97 -> 7200.22 | E37: ='Assumption Sheet'!E97 -> 9882.27 | F37: ='Assumption Sheet'!F97 -> 17218.87 | G37: 27593.71 | H37: 27593.71 | I37: 27593.71 | J37: 7486.15 | K37: =J37*(1+6%) -> 7935.319
A38: Worst Scenario | B38: Out of 1000 Cr, 172.19 Cr is invested remaning 827.81Cr over 4 years | C38: ='Assumption Sheet'!C97 -> 5209.07 | D38: ='Assumption Sheet'!D97 -> 7200.22 | E38: ='Assumption Sheet'!E97 -> 9882.27 | F38: ='Assumption Sheet'!F97 -> 17218.87 | G38: 20695.283 | H38: 20695.283 | I38: 20695.283 | J38: 20695.283 | K38: 7486.15
A40: Growth Rate | B40: 2
A41: Best Scenario | B41: 0.07
A42: Base Scenario | B42: 0.05
A43: Worst Scenario | B43: 0.03
A46: Thesis
A47: Right for 60 years | B47: 5 year payback
A48: Gen Ai for video
A49: Spotify will be a paid app eventually | B49: 0.1 Paisa per stream for free , 0.50 paisa per stream for paid
A50: Focus on short video , reels format are trending
A51: Annuity type structure
A52: Old Songs collection
A54: Anti thesis
...

Sheet Assumption Sheet
A1: Assumption Sheet
A2: Figures in Lakhs ,expect otherwise stated
A3: Particular/Years | B3: Comments | C3: 2021-22 A | D3: 2022-23 A | E3: 2023-24 A | F3: 2024-25 A | G3: 2025-26 E | H3: 2026-27 E | I3: 2027-28 E | J3: 2028-29 E | K3: 2029-30 E
A5: Revenue Model
A7: ='Revenue Model'!A18 -> Sale of product
A8: ='Revenue Model'!A21 -> Y-o-Y Growth in Sale in Quantity of Products | B8: Mgmnt Guidance- Mgmnt will not focus much on this segment and rather focus on music segment | C8: ='Revenue Model'!C21 -> - | D8: ='Revenue Model'!D21 -> 0.39900249 | E8: ='Revenue Model'!E21 -> 0.2228164 | F8: ='Revenue Model'!F21 -> -0.36734694 | G8: =CHOOSE('Scenario Analysis '!$B$7,'Scenario Analysis '!G8,'Scenario Analysis '!G9,'Scenario Analysis '!G10) -> -0.2 | H8: =CHOOSE('Scenario Analysis '!$B$7,'Scenario Analysis '!H8,'Scenario Analysis '!H9,'Scenario Analysis '!H10) -> -0.2 | I8: =CHOOSE('Scenario Analysis '!$B$7,'Scenario Analysis '!I8,'Scenario Analysis '!I9,'Scenario Analysis '!I10) -> -0.2 | J8: =CHOOSE('Scenario Analysis '!$B$7,'Scenario Analysis '!J8,'Scenario Analysis '!J9,'Scenario Analysis '!J10) -> -0.2 | K8: =CHOOSE('Scenario Analysis '!$B$7,'Scenario Analysis '!K8,'Scenario Analysis '!K9,'Scenario Analysis '!K10) -> -0.2
A9: ='Revenue Model'!A22 -> Y-o-Y Growth in Average Selling Price of Products | B9: Mgmnt Guidance- Mgmnt will not focus much on this segment and rather focus on music segment | C9: ='Revenue Model'!C22 -> - | D9: ='Revenue Model'!D22 -> -0.10290123 | E9: ='Revenue Model'!E22 -> -0.16933017 | F9: ='Revenue Model'!F22 -> -0.0056007884 | G9: -0.2 | H9: -0.2 | I9: -0.2 | J9: -0.2 | K9: -0.2
A11: License Fees- Music
A12: ='Revenue Model'!A42 -> Era wise Segment (YoY Growth in Revenue)
A13: ='Revenue Model'!A44 -> 2001-2020 | B13: Mgmnt Guidance | C13: ='Revenue Model'!C44 -> - | D13: ='Revenue Model'!D44 -> -0.39997017 | E13: ='Revenue Model'!E44 -> 0.042213282 | F13: ='Revenue Model'!F44 -> -0.051684909 | G13: 0.06 | H13: 0.06 | I13: 0.06 | J13: 0.06 | K13: 0.06
A14: ='Revenue Model'!A45 -> 1981-2000 | B14: Mgmnt Guidance | C14: ='Revenue Model'!C45 -> - | D14: ='Revenue Model'!D45 -> -0.076877182 | E14: ='Revenue Model'!E45 -> 0.097066613 | F14: ='Revenue Model'!F45 -> 0.013511754 | G14: 0.06 | H14: 0.06 | I14: 0.06 | J14: 0.06 | K14: 0.06
A15: ='Revenue Model'!A46 -> 1961-1980 | B15: Mgmnt Guidance | C15: ='Revenue Model'!C46 -> - | D15: ='Revenue Model'!D46 -> 0.084672907 | E15: ='Revenue Model'!E46 -> -0.021151772 | F15: ='Revenue Model'!F46 -> 0.036034237 | G15: 0.06 | H15: 0.06 | I15: 0.06 | J15: 0.06 | K15: 0.06
A16: ='Revenue Model'!A47 -> Till 1960 | B16: Explicit | C16: ='Revenue Model'!C47 -> - | D16: ='Revenue Model'!D47 -> 0.0048808775 | E16: ='Revenue Model'!E47 -> 0.31015071 | F16: ='Revenue Model'!F47 -> 0.12612417 | G16: 0.04 | H16: 0.04 | I16: 0.04 | J16: 0.04 | K16: 0.04
A18: ='Revenue Model'!A65 -> Y-o-Y Increase in Number of Songs After 2021 | C18: ='Revenue Model'!C65 -> - | D18: ='Revenue Model'!D65 -> 0.12 | E18: ='Revenue Model'!E65 -> 0.104 | F18: ='Revenue Model'!F65 -> 0.056 | G18: =G19*G20 -> 0.06 | H18: =H19*H20 -> 0.066 | I18: =I19*I20 -> 0.046 | J18: =J19*J20 -> 0.048 | K18: =K19*K20 -> 0.05
A19: % of New Content Acquried by Saregama | B19: Mgmnt Guidance- 30% till FY 2027 | C19: - | D19: - | E19: - | F19: - | G19: 0.3 | H19: 0.3 | I19: 0.2 | J19: 0.2 | K19: 0.2
A20: New Songs made per Year (In Lkahs) | B20: Report by EY | C20: - | D20: - | E20: - | F20: - | G20: 0.2 | H20: 0.22 | I20: 0.23 | J20: 0.24 | K20: 0.25
A22: ='Revenue Model'!A75 -> Y-o-Y Increase in Revenue per song of Songs After 2021 | C22: ='Revenue Model'!C75 -> 0 | D22: ='Revenue Model'!D75 -> 0 | E22: ='Revenue Model'!E75 -> -0.25654146 | F22: ='Revenue Model'!F75 -> 0.091999196 | G22: =CHOOSE('Scenario Analysis '!$B$13,'Scenario Analysis '!G14,'Scenario Analysis '!G15,'Scenario Analysis '!G16) -> 0.15 | H22: =CHOOSE('Scenario Analysis '!$B$13,'Scenario Analysis '!H14,'Scenario Analysis '!H15,'Scenario Analysis '!H16) -> 0.2 | I22: =CHOOSE('Scenario Analysis '!$B$13,'Scenario Analysis '!I14,'Scenario Analysis '!I15,'Scenario Analysis '!I16) -> 0.1 | J22: =CHOOSE('Scenario Analysis '!$B$13,'Scenario Analysis '!J14,'Scenario Analysis '!J15,'Scenario Analysis '!J16) -> 0.08 | K22: =CHOOSE('Scenario Analysis '!$B$13,'Scenario Analysis '!K14,'Scenario Analysis '!K15,'Scenario Analysis '!K16) -> 0.09
A24: Artist Management
A25: ='Revenue Model'!A79 -> Y-o-Y Growth in music Segment | C25: ='Revenue Model'!C79 -> 0 | D25: ='Revenue Model'!D79 -> 0.15947794 | E25: ='Revenue Model'!E79 -> 0.1847445 | F25: ='Revenue Model'!F79 -> 0.21817235 | G25: =CHOOSE('Scenario Analysis '!$B$19,'Scenario Analysis '!G20,'Scenario Analysis '!G21,'Scenario Analysis '!G22) -> 0.21 | H25: =CHOOSE('Scenario Analysis '!$B$19,'Scenario Analysis '!H20,'Scenario Analysis '!H21,'Scenario Analysis '!H22) -> 0.21 | I25: =CHOOSE('Scenario Analysis '!$B$19,'Scenario Analysis '!I20,'Scenario Analysis '!I21,'Scenario Analysis '!I22) -> 0.21 | J25: =CHOOSE('Scenario Analysis '!$B$19,'Scenario Analysis '!J20,'Scenario Analysis '!J21,'Scenario Analysis '!J22) -> 0.21 | K25: =CHOOSE('Scenario Analysis '!$B$19,'Scenario Analysis '!K20,'Scenario Analysis '!K21,'Scenario Analysis '!K22) -> 0.21
A27: Income from videos
A28: ='Revenue Model'!A83 -> Y-o-Y Growth in Video Segment | C28: ='Revenue Model'!C83 -> - | D28: ='Revenue Model'!D83 -> 0.059298007 | E28: ='Revenue Model'!E83 -> 0.068260207 | F28: ='Revenue Model'!F83 -> 0.65688473 | G28: =CHOOSE('Scenario Analysis '!$B$24,'Scenario Analysis '!G25,'Scenario Analysis '!G26,'Scenario Analysis '!G27) -> 0.15 | H28: =CHOOSE('Scenario Analysis '!$B$24,'Scenario Analysis '!H25,'Scenario Analysis '!H26,'Scenario Analysis '!H27) -> 0.15 | I28: =CHOOSE('Scenario Analysis '!$B$24,'Scenario Analysis '!I25,'Scenario Analysis '!I26,'Scenario Analysis '!I27) -> 0.15 | J28: =CHOOSE('Scenario Analysis '!$B$24,'Scenario Analysis '!J25,'Scenario Analysis '!J26,'Scenario Analysis '!J27) -> 0.15 | K28: =CHOOSE('Scenario Analysis '!$B$24,'Scenario Analysis '!K25,'Scenario Analysis '!K26,'Scenario Analysis '!K27) -> 0.15
A30: Income from events
A31: ='Revenue Model'!A86 -> Y-o-Y Growth in Events Segment | B31: Expilict- Lumpier segment of the business. | C31: ='Revenue Model'!C86 -> 0 | D31: ='Revenue Model'!D86 -> 0 | E31: ='Revenue Model'!E86 -> -0.72543641 | F31: ='Revenue Model'!F86 -> 20.220619 | G31: =CHOOSE('Scenario Analysis '!$B$30,'Scenario Analysis '!G31,'Scenario Analysis '!G32,'Scenario Analysis '!G33) -> -0.1 | H31: =CHOOSE('Scenario Analysis '!$B$30,'Scenario Analysis '!H31,'Scenario Analysis '!H32,'Scenario Analysis '!H33) -> -0.1 | I31: =CHOOSE('Scenario Analysis '!$B$30,'Scenario Analysis '!I31,'Scenario Analysis '!I32,'Scenario Analysis '!I33) -> -0.1 | J31: =CHOOSE('Scenario Analysis '!$B$30,'Scenario Analysis '!J31,'Scenario Analysis '!J32,'Scenario Analysis '!J33) -> -0.1 | K31: =CHOOSE('Scenario Analysis '!$B$30,'Scenario Analysis '!K31,'Scenario Analysis '!K32,'Scenario Analysis '!K33) -> -0.1
A33: Other operating income
A34: ='Revenue Model'!A88 -> Other operating income | B34: Explicit | C34: ='Revenue Model'!C88 -> 1327.06 | D34: ='Revenue Model'!D88 -> 3036.74 | E34: ='Revenue Model'!E88 -> 4503.17 | F34: ='Revenue Model'!F88 -> 467.2 | G34: 0 | H34: 0 | I34: 0 | J34: 0 | K34: 0
A37: Cost Model
A39: ='Cost Model '!A5 -> Cost of Music Business
A40: ='Cost Model '!A12 -> Cost of music/Income from music | B40: Constant Average | C40: ='Cost Model '!C12 -> 0.14866215 | D40: ='Cost Model '!D12 -> 0.16563742 | E40: ='Cost Model '!E12 -> 0.17010661 | F40: ='Cost Model '!F12 -> 0.12630644 | G40: =AVERAGE($C$40:$F$40) -> 0.15267816 | H40: =AVERAGE($C$40:$F$40) -> 0.15267816 | I40: =AVERAGE($C$40:$F$40) -> 0.15267816 | J40: =AVERAGE($C$40:$F$40) -> 0.15267816 | K40: =AVERAGE($C$40:$F$40) -> 0.15267816
A42: ='Cost Model '!A15 -> Cost of Films, Tv serials and Digital content (under production and untelecasted)
A43: ='Cost Model '!A21 -> Cost of films and events/Income from films and events | B43: Explicit - with gen AI time and cost of production will reduce eventually | C43: ='Cost Model '!C21 -> 0.72255651 | D43: ='Cost Model '!D21 -> 0.85209774 | E43: ='Cost Model '!E21 -> 0.96749629 | F43: ='Cost Model '!F21 -> 0.9555422 | G43: 0.8 | H43: 0.8 | I43: 0.75 | J43: 0.7 | K43: 0.7
A45: ='Cost Model '!A24 -> Employee benefits expense
A46: ='Cost Model '!A26 -> No. of BOD | C46: ='Cost Model '!C26 -> 0 | D46: ='Cost Model '!D26 -> 8 | E46: ='Cost Model '!E26 -> 7 | F46: ='Cost Model '!F26 -> 8 | G46: 8 | H46: 8 | I46: 8 | J46: 8 | K46: 8
A47: ='Cost Model '!A28 -> YoY Increase in Median Salary of BOD | B47: Constant Average | C47: ='Cost Model '!C28 -> - | D47: ='Cost Model '!D28 -> - | E47: ='Cost Model '!E28 -> 0 | F47: ='Cost Model '!F28 -> 0.7654321 | G47: =AVERAGE($E$47:$F$47) -> 0.38271605 | H47: =AVERAGE($E$47:$F$47) -> 0.38271605 | I47: =AVERAGE($E$47:$F$47) -> 0.38271605 | J47: =AVERAGE($E$47:$F$47) -> 0.38271605 | K47: =AVERAGE($E$47:$F$47) -> 0.38271605
A49: ='Cost Model '!A30 -> No. of KMP (Key Managerial Personell) | C49: ='Cost Model '!C30 -> 3 | D49: ='Cost Model '!D30 -> 3 | E49: ='Cost Model '!E30 -> 3 | F49: ='Cost Model '!F30 -> 3 | G49: 3 | H49: 3 | I49: 3 | J49: 3 | K49: 3
A50: ='Cost Model '!A32 -> YoY Increase in Median Salary of BOD | B50: Rolling average of 3 years | C50: ='Cost Model '!C32 -> - | D50: ='Cost Model '!D32 -> 0.47750211 | E50: ='Cost Model '!E32 -> 0.19687384 | F50: ='Cost Model '!F32 -> 0.1899768 | G50: =AVERAGE(D50:F50) -> 0.28811759 | H50: =AVERAGE(E50:G50) -> 0.22498941 | I50: =AVERAGE(F50:H50) -> 0.23436127 | J50: =AVERAGE(G50:I50) -> 0.24915609 | K50: =AVERAGE(H50:J50) -> 0.23616892
A52: ='Cost Model '!A34 -> Total Number of Employees (Other than BOD and KMP) | C52: ='Cost Model '!C34 -> 407 | D52: ='Cost Model '!D34 -> 372 | E52: ='Cost Model '!E34 -> 454 | F52: ='Cost Model '!F34 -> 396 | G52: =F52+G53 -> 446 | H52: =G52+H53 -> 496 | I52: =H52+I53 -> 546 | J52: =I52+J53 -> 596 | K52: =J52+K53 -> 646
A53: YoY Increase in No. of Employee | B53: Explicit - With Gen AI | D53: =D52-C52 -> -35 | E53: =E52-D52 -> 82 | F53: =F52-E52 -> -58 | G53: 50 | H53: 50 | I53: 50 | J53: 50 | K53: 50
A54: ='Cost Model '!A36 -> YoY Increase in Median Salary of Employee (Other than BOD and KMP) | C54: ='Cost Model '!C36 -> - | D54: ='Cost Model '!D36 -> - | E54: ='Cost Model '!E36 -> -0.042631579 | F54: ='Cost Model '!F36 -> 0.21330401 | G54: 0.3 | H54: 0.3 | I54: 0.3 | J54: 0.3 | K54: 0.3
A56: ='Cost Model '!A39 -> Royalty expenses
A57: ='Cost Model '!A41 -> Royalty Expense / License Income | B57: Constant | C57: ='Cost Model '!C41 -> 0.17379466 | D57: ='Cost Model '!D41 -> 0.15562538 | E57: ='Cost Model '!E41 -> 0.1280958 | F57: ='Cost Model '!F41 -> 0.12683352 | G57: 0.11 | H57: 0.11 | I57: 0.11 | J57: 0.11 | K57: 0.11
...

Sheet Balance Sheet
A1: Balance Sheet
A2: Figures in Lakhs ,expect otherwise stated
A3: Particular/Years | B3: Comments | C3: 2021-22 A | D3: 2022-23 A | E3: 2023-24 A | F3: 2024-25 A | G3: 2025-26 E | H3: 2026-27 E | I3: 2027-28 E | J3: 2028-29 E | K3: 2029-30 E
A4: ASSETS
A5: Non-current assets
A6: Property, plant and equipment | B6: Capex Schedule | C6: 21411.36 | D6: 22065.72 | E6: 22382.16 | F6: 22222.07 | G6: ='Capex Schedule '!G135 -> 22219.969 | H6: ='Capex Schedule '!H135 -> 22189.73 | I6: ='Capex Schedule '!I135 -> 22066.614 | J6: ='Capex Schedule '!J135 -> 21905.306 | K6: ='Capex Schedule '!K135 -> 21788.241
A7: Right-of-use assets | B7: Lease Schedule | C7: 125.88 | D7: 66.6 | E7: 334.55 | F7: 212.3 | G7: ='Lease Schedule '!G14 -> 89.9 | H7: ='Lease Schedule '!H14 -> 69.9 | I7: ='Lease Schedule '!I14 -> 49.9 | J7: ='Lease Schedule '!J14 -> 29.9 | K7: ='Lease Schedule '!K14 -> 9.9
A8: Investment property | B8: Capex Schedule | C8: 219.49 | D8: 213.95 | E8: 208.41 | F8: 202.87 | G8: ='Capex Schedule '!G315 -> 197.33 | H8: ='Capex Schedule '!H315 -> 191.79 | I8: ='Capex Schedule '!I315 -> 186.25 | J8: ='Capex Schedule '!J315 -> 180.71 | K8: ='Capex Schedule '!K315 -> 175.17
A9: Intangible assets | B9: Capex Schedule | C9: 6016.67 | D9: 11425.83 | E9: 51299.48 | F9: 60823.32 | G9: ='Capex Schedule '!G297 -> 81430.973 | H9: ='Capex Schedule '!H297 -> 99149.246 | I9: ='Capex Schedule '!I297 -> 113988.15 | J9: ='Capex Schedule '!J297 -> 107905.25 | K9: ='Capex Schedule '!K297 -> 101518.28
A10: Intangible assets under development | B10: Constant | C10: 174.52 | D10: 404.98 | E10: 554.03 | F10: 0 | G10: 0 | H10: 0 | I10: 0 | J10: 0 | K10: 0
A11: Investment accounted using equity method | B11: Constant | C11: 0 | D11: 0 | E11: 0 | F11: 0 | G11: 0 | H11: 0 | I11: 0 | J11: 0 | K11: 0
A12: Other financial assets | B12: Constant | C12: 14725.69 | D12: 5295.59 | E12: 1719.12 | F12: 779.76 | G12: 779.76 | H12: 779.76 | I12: 779.76 | J12: 779.76 | K12: 779.76
A13: Other non-current assets | B13: Constant | C13: 2915.61 | D13: 5734.75 | E13: 4675.37 | F13: 5007.8 | G13: 5007.8 | H13: 5007.8 | I13: 5007.8 | J13: 5007.8 | K13: 5007.8
A14: Total non-current assets | C14: =SUM(C6:C13) -> 45589.22 | D14: =SUM(D6:D13) -> 45207.42 | E14: =SUM(E6:E13) -> 81173.12 | F14: =SUM(F6:F13) -> 89248.12 | G14: =SUM(G6:G13) -> 109725.73 | H14: =SUM(H6:H13) -> 127388.23 | I14: =SUM(I6:I13) -> 142078.47 | J14: =SUM(J6:J13) -> 135808.73 | K14: =SUM(K6:K13) -> 129279.15
A15: Current assets
A16: Inventories | B16: WC Schedule | C16: 10543.83 | D16: 16425.56 | E16: 23925.83 | F16: 24021.48 | G16: ='WC Schedule '!G39 -> 15059.714 | H16: ='WC Schedule '!H39 -> 17079.15 | I16: ='WC Schedule '!I39 -> 19764.118 | J16: ='WC Schedule '!J39 -> 23184.466 | K16: ='WC Schedule '!K39 -> 27448.175
A17: Investments | B17: Constant | C17: 53076.37 | D17: 23877.46 | E17: 11772.39 | F17: 11120.75 | G17: 11120.75 | H17: 11120.75 | I17: 11120.75 | J17: 11120.75 | K17: 11120.75
A18: Trade receivables | B18: WC Schedule | C18: 10780.25 | D18: 14796.95 | E18: 15873.78 | F18: 14321.51 | G18: ='WC Schedule '!G47 -> 20798.883 | H18: ='WC Schedule '!H47 -> 23151.693 | I18: ='WC Schedule '!I47 -> 26272.793 | J18: ='WC Schedule '!J47 -> 30242.165 | K18: ='WC Schedule '!K47 -> 35179.981
A19: Cash and cash equivalents | B19: CFS | C19: 15272.6 | D19: 1670.34 | E19: 5691.91 | F19: 6939.1 | G19: =CFS!G60 -> 13673.698 | H19: =CFS!H60 -> 21073.936 | I19: =CFS!I60 -> 21020.624 | J19: =CFS!J60 -> 46714.392 | K19: =CFS!K60 -> 76591.321
A20: Bank balances (other than cash) | B20: Constant | C20: 17100.96 | D20: 49156.33 | E20: 48517.08 | F20: 47430.52 | G20: 47430.52 | H20: 47430.52 | I20: 47430.52 | J20: 47430.52 | K20: 47430.52
A21: Loans | B21: Constant | C21: 2282.09 | D21: 2621.31 | E21: 2209.22 | F21: 1925.33 | G21: 1925.33 | H21: 1925.33 | I21: 1925.33 | J21: 1925.33 | K21: 1925.33
A22: Other financial assets | B22: Constant | C22: 793.02 | D22: 2195.84 | E22: 311.7 | F22: 326.64 | G22: 326.64 | H22: 326.64 | I22: 326.64 | J22: 326.64 | K22: 326.64
A23: Current tax assets (net) | B23: Constant | C23: 2566.85 | D23: 3013.25 | E23: 2750.12 | F23: 3587.66 | G23: 3587.66 | H23: 3587.66 | I23: 3587.66 | J23: 3587.66 | K23: 3587.66
A24: Other current assets | B24: Constant | C24: 10782.24 | D24: 11446.1 | E24: 11153.33 | F24: 10594.83 | G24: 10594.83 | H24: 10594.83 | I24: 10594.83 | J24: 10594.83 | K24: 10594.83
A25: Total current assets | C25: =SUM(C16:C24) -> 123198.21 | D25: =SUM(D16:D24) -> 125203.14 | E25: =SUM(E16:E24) -> 122205.36 | F25: =SUM(F16:F24) -> 120267.82 | G25: =SUM(G16:G24) -> 124518.02 | H25: =SUM(H16:H24) -> 136290.51 | I25: =SUM(I16:I24) -> 142043.26 | J25: =SUM(J16:J24) -> 175126.75 | K25: =SUM(K16:K24) -> 214205.21
A27: TOTAL ASSETS | C27: =C14+C25 -> 168787.43 | D27: =D14+D25 -> 170410.56 | E27: =E14+E25 -> 203378.48 | F27: =F14+F25 -> 209515.94 | G27: =G14+G25 -> 234243.76 | H27: =H14+H25 -> 263678.74 | I27: =I14+I25 -> 284121.74 | J27: =J14+J25 -> 310935.48 | K27: =K14+K25 -> 343484.35
A29: EQUITY AND LIABILITIES
A30: Equity
A31: Equity share capital | B31: Constant | C31: 1928.09 | D31: 1928.09 | E31: 1928.09 | F31: 1928.09 | G31: 1928.09 | H31: 1928.09 | I31: 1928.09 | J31: 1928.09 | K31: 1928.09
A32: Other equity | B32: Opening + EAESH | C32: 135841.62 | D32: 132282.92 | E32: 144984.18 | F32: 156409.8 | G32: =F32+IS!G21 -> 181535.32 | H32: =G32+IS!H21 -> 208420.08 | I32: =H32+IS!I21 -> 228345.45 | J32: =I32+IS!J21 -> 254315.42 | K32: =J32+IS!K21 -> 284921.66
A33: Equity attributable to owners | C33: =SUM(C31:C32) -> 137769.71 | D33: =SUM(D31:D32) -> 134211.01 | E33: =SUM(E31:E32) -> 146912.27 | F33: =SUM(F31:F32) -> 158337.89 | G33: =SUM(G31:G32) -> 183463.41 | H33: =SUM(H31:H32) -> 210348.17 | I33: =SUM(I31:I32) -> 230273.54 | J33: =SUM(J31:J32) -> 256243.51 | K33: =SUM(K31:K32) -> 286849.75
A34: Non-controlling interest | B34: Constant | C34: 323.42 | D34: 338.52 | E34: 344.58 | F34: 338.22 | G34: 338.22 | H34: 338.22 | I34: 338.22 | J34: 338.22 | K34: 338.22
A35: Total equity | C35: =SUM(C33:C34) -> 138093.13 | D35: =SUM(D33:D34) -> 134549.53 | E35: =SUM(E33:E34) -> 147256.85 | F35: =SUM(F33:F34) -> 158676.11 | G35: =SUM(G33:G34) -> 183801.63 | H35: =SUM(H33:H34) -> 210686.39 | I35: =SUM(I33:I34) -> 230611.76 | J35: =SUM(J33:J34) -> 256581.73 | K35: =SUM(K33:K34) -> 287187.97
A37: Non-current liabilities
A38: Lease liabilities | B38: Lease Schedule | C38: 71.25 | D38: 13.78 | E38: 225.65 | F38: 141.43 | G38: ='Lease Schedule '!G29 -> 105.2835 | H38: ='Lease Schedule '!H29 -> 73.7813 | I38: ='Lease Schedule '!I29 -> 51.70497 | J38: ='Lease Schedule '!J29 -> 36.234168 | K38: ='Lease Schedule '!K29 -> 25.392431
A39: Other financial liabilities | B39: Constant | C39: 0 | D39: 0 | E39: 20895 | F39: 3094 | G39: 3094 | H39: 3094 | I39: 3094 | J39: 3094 | K39: 3094
A40: Provisions | B40: Constant | C40: 418.95 | D40: 414.26 | E40: 569.53 | F40: 586.21 | G40: 586.21 | H40: 586.21 | I40: 586.21 | J40: 586.21 | K40: 586.21
A41: Deferred tax liabilities (net) | B41: Constant | C41: 5616.02 | D41: 4637.73 | E41: 4744.47 | F41: 5182.28 | G41: 5182.28 | H41: 5182.28 | I41: 5182.28 | J41: 5182.28 | K41: 5182.28
A42: Total non-current liabilities | C42: =SUM(C38:C41) -> 6106.22 | D42: =SUM(D38:D41) -> 5065.77 | E42: =SUM(E38:E41) -> 26434.65 | F42: =SUM(F38:F41) -> 9003.92 | G42: =SUM(G38:G41) -> 8967.7735 | H42: =SUM(H38:H41) -> 8936.2713 | I42: =SUM(I38:I41) -> 8914.195 | J42: =SUM(J38:J41) -> 8898.7242 | K42: =SUM(K38:K41) -> 8887.8824
A44: Current liabilities
...

Sheet IS
A1: Income Statement
A2: Figures in Lakhs ,expect otherwise stated
A3: Particular/Years | B3: Comments | C3: 2021-22 A | D3: 2022-23 A | E3: 2023-24 A | F3: 2024-25 A | G3: 2025-26 E | H3: 2026-27 E | I3: 2027-28 E | J3: 2028-29 E | K3: 2029-30 E
A4: Revenue from operations | C4: 58062.76 | D4: 73662.12 | E4: 80300.4 | F4: 117135.76 | G4: ='Revenue Model'!G5 -> 126526.54 | H4: ='Revenue Model'!H5 -> 140839.47 | I4: ='Revenue Model'!I5 -> 159826.15 | J4: ='Revenue Model'!J5 -> 183973.17 | K4: ='Revenue Model'!K5 -> 214011.55
A5: Cost of Music Business | B5: Opening - Transferred from arrangement+Purchase-Closing | C5: ='WC Schedule '!C10 -> 6912.28 | D5: ='WC Schedule '!D10 -> 9090.75 | E5: ='WC Schedule '!E10 -> 10693.99 | F5: ='WC Schedule '!F10 -> 8708.41 | G5: ='Cost Model '!G5 -> 12027.589 | H5: ='Cost Model '!H5 -> 14099.201 | I5: ='Cost Model '!I5 -> 16769.356 | J5: ='Cost Model '!J5 -> 20104.888 | K5: ='Cost Model '!K5 -> 24207.853
A6: Cost of Films, Tv serials and Digital content (under production and untelecasted) | B6: Opening+Purchase-Closing | C6: ='WC Schedule '!C16 -> 7398.35 | D6: ='WC Schedule '!D16 -> 13413.68 | E6: ='WC Schedule '!E16 -> 12510.53 | F6: ='WC Schedule '!F16 -> 45600.27 | G6: ='Cost Model '!G15 -> 38199.306 | H6: ='Cost Model '!H15 -> 38794.86 | I6: ='Cost Model '!I15 -> 37493.608 | J6: ='Cost Model '!J15 -> 36604.174 | K6: ='Cost Model '!K15 -> 38819.732
A7: Employee benefits expense | C7: 7344.7 | D7: 7499.89 | E7: 9316.06 | F7: 10749.67 | G7: ='Cost Model '!G24 -> 8073.2067 | H7: ='Cost Model '!H24 -> 11308.212 | I7: ='Cost Model '!I24 -> 15785.883 | J7: ='Cost Model '!J24 -> 21978.012 | K7: ='Cost Model '!K24 -> 30431.48
A8: Royalty expenses | C8: 6313.76 | D8: 6555.33 | E8: 6126.64 | F8: 6831.37 | G8: ='Cost Model '!G39 -> 7073.924 | H8: ='Cost Model '!H39 -> 8728.8623 | I8: ='Cost Model '!I39 -> 10029.449 | J8: ='Cost Model '!J39 -> 11409.412 | K8: ='Cost Model '!K39 -> 13054.199
A9: Advertisement and sales promotion | C9: 5205.33 | D9: 7710.99 | E9: 7598.01 | F9: 9041.17 | G9: ='Cost Model '!G44 -> 11581.474 | H9: ='Cost Model '!H44 -> 12891.593 | I9: ='Cost Model '!I44 -> 14629.52 | J9: ='Cost Model '!J44 -> 16839.792 | K9: ='Cost Model '!K44 -> 19589.324
A10: Other expenses | C10: 6176.07 | D10: 7293.41 | E10: 9400.07 | F10: 8506.01 | G10: ='Cost Model '!G49 -> 12496.347 | H10: ='Cost Model '!H49 -> 13642.214 | I10: ='Cost Model '!I49 -> 15395.502 | J10: ='Cost Model '!J49 -> 16767.841 | K10: ='Cost Model '!K49 -> 20496.829
A11: Earning Before Interest, Tax, Depriciation and Amortization | C11: =C4-SUM(C5:C10) -> 18712.27 | D11: =D4-SUM(D5:D10) -> 22098.07 | E11: =E4-SUM(E5:E10) -> 24655.1 | F11: =F4-SUM(F5:F10) -> 27698.86 | G11: =G4-SUM(G5:G10) -> 37074.691 | H11: =H4-SUM(H5:H10) -> 41374.525 | I11: =I4-SUM(I5:I10) -> 49722.838 | J11: =J4-SUM(J5:J10) -> 60269.054 | K11: =K4-SUM(K5:K10) -> 67412.135
A12: Depreciation and amortisation expense | C12: 1310.1 | D12: 2081.95 | E12: 3618.18 | F12: 5821.08 | G12: ='Depreciation & Finance Cost '!G29 -> 7974.5866 | H12: ='Depreciation & Finance Cost '!H29 -> 10738.498 | I12: ='Depreciation & Finance Cost '!I29 -> 13602.852 | J12: ='Depreciation & Finance Cost '!J29 -> 14395.803 | K12: ='Depreciation & Finance Cost '!K29 -> 15254.25
A13: Earning Before Interest and Tax (EBIT) | C13: =C11-C12 -> 17402.17 | D13: =D11-D12 -> 20016.12 | E13: =E11-E12 -> 21036.92 | F13: =F11-F12 -> 21877.78 | G13: =G11-G12 -> 29100.105 | H13: =H11-H12 -> 30636.027 | I13: =I11-I12 -> 36119.985 | J13: =J11-J12 -> 45873.251 | K13: =K11-K12 -> 52157.885
A14: Finance costs | C14: 451.94 | D14: 571.48 | E14: 324.21 | F14: 574.15 | G14: ='Depreciation & Finance Cost '!G37 -> 153.11296 | H14: ='Depreciation & Finance Cost '!H37 -> 144.20856 | I14: ='Depreciation & Finance Cost '!I37 -> 137.96847 | J14: ='Depreciation & Finance Cost '!J37 -> 133.5955 | K14: ='Depreciation & Finance Cost '!K37 -> 130.53098
A15: Exceptional Items (Net) | C15: 0 | D15: 0 | E15: 0 | F15: -496.21 | G15: 0 | H15: 0 | I15: 0 | J15: 0 | K15: 0
A16: Other income | C16: 3491.01 | D16: 5363.13 | E16: 6365.86 | F16: 5807.26 | G16: ='Other Income Schedule '!G19 -> 4982.564 | H16: ='Other Income Schedule '!H19 -> 5813.4197 | I16: ='Other Income Schedule '!I19 -> 7185.4836 | J16: ='Other Income Schedule '!J19 -> 10523.207 | K16: ='Other Income Schedule '!K19 -> 14279.788
A17: Earning before Tax (EBT) | C17: =C13-C14-C15+C16 -> 20441.24 | D17: =D13-D14-D15+D16 -> 24807.77 | E17: =E13-E14-E15+E16 -> 27078.57 | F17: =F13-F14-F15+F16 -> 27607.1 | G17: =G13-G14+G15+G16 -> 33929.556 | H17: =H13-H14+H15+H16 -> 36305.238 | I17: =I13-I14+I15+I16 -> 43167.5 | J17: =J13-J14+J15+J16 -> 56262.862 | K17: =K13-K14+K15+K16 -> 66307.142
A18: Tax Expense | C18: 5176.68 | D18: 6302.58 | E18: 7322.64 | F18: 7183.2 | G18: ='Cost Model '!G54 -> 8804.0365 | H18: ='Cost Model '!H54 -> 9420.4782 | I18: ='Cost Model '!I54 -> 11201.097 | J18: ='Cost Model '!J54 -> 14599.08 | K18: ='Cost Model '!K54 -> 17205.368
A19: Profit For the year | C19: =C17-C18 -> 15264.56 | D19: =D17-D18 -> 18505.19 | E19: =E17-E18 -> 19755.93 | F19: =F17-F18 -> 20423.9 | G19: =G17-G18 -> 25125.519 | H19: =H17-H18 -> 26884.76 | I19: =I17-I18 -> 31966.403 | J19: =J17-J18 -> 41663.782 | K19: =K17-K18 -> 49101.774
A20: Dividends | C20: 5784.28 | D20: 5784.28 | E20: 7712.38 | F20: 8676.4 | G20: ='Cost Model '!G59 -> 0 | H20: ='Cost Model '!H59 -> 0 | I20: ='Cost Model '!I59 -> 12041.028 | J20: ='Cost Model '!J59 -> 15693.814 | K20: ='Cost Model '!K59 -> 18495.539
A21: Earnings available to equity shareholders (EAESH) | C21: =C19-C20 -> 9480.28 | D21: =D19-D20 -> 12720.91 | E21: =E19-E20 -> 12043.55 | F21: =F19-F20 -> 11747.5 | G21: =G19-G20 -> 25125.519 | H21: =H19-H20 -> 26884.76 | I21: =I19-I20 -> 19925.375 | J21: =J19-J20 -> 25969.969 | K21: =K19-K20 -> 30606.235
A24: Other comprehensive income
A25: Items that will be reclassified to profit or loss:
A26: (a) Exchange differences on translation of foreign operations | C26: 26.4 | D26: 176.41 | E26: 45.83 | F26: 22.88 | G26: 0 | H26: 0 | I26: 0 | J26: 0 | K26: 0
A27: Items that will not be reclassified subsequently to profit or loss:
A28: (a) Remeasurements of post-employment benefit obligations | C28: 115.37 | D28: 8.02 | E28: -138.23 | F28: -78.2 | G28: 0 | H28: 0 | I28: 0 | J28: 0 | K28: 0
A29: (b) Changes in fair value of equity instruments designated at FVOCI | C29: 3385.69 | D29: 0 | E29: 0 | F29: 0 | G29: 0 | H29: 0 | I29: 0 | J29: 0 | K29: 0
A30: (c) Revaluation gains relating to property, plant and equipment | C30: 959.44 | D30: 0 | E30: 0 | F30: 0 | G30: 0 | H30: 0 | I30: 0 | J30: 0 | K30: 0
A31: (d) Income tax relating to items that will not be reclassified subsequently to profit or loss | C31: -643.37 | D31: -2.02 | E31: 36.42 | F31: 20.75 | G31: 0 | H31: 0 | I31: 0 | J31: 0 | K31: 0
A32: Other comprehensive income for the year, net of tax | C32: =SUM(C26:C31) -> 3843.53 | D32: =SUM(D26:D31) -> 182.41 | E32: =SUM(E26:E31) -> -55.98 | F32: =SUM(F26:F31) -> -34.57 | G32: =SUM(G26:G31) -> 0 | H32: =SUM(H26:H31) -> 0 | I32: =SUM(I26:I31) -> 0 | J32: =SUM(J26:J31) -> 0 | K32: =SUM(K26:K31) -> 0
A34: Total comprehensive income for the year | C34: =C19+C32 -> 19108.09 | D34: =D19+D32 -> 18687.6 | E34: =E19+E32 -> 19699.95 | F34: =F19+F32 -> 20389.33 | G34: =G19+G32 -> 25125.519 | H34: =H19+H32 -> 26884.76 | I34: =I19+I32 -> 31966.403 | J34: =J19+J32 -> 41663.782 | K34: =K19+K32 -> 49101.774

Sheet CFS
A1: Cash Flow Statement
A2: Figures in Lakhs ,expect otherwise stated
A3: Particular/Years | B3: Comments | C3: 2021-22 A | D3: 2022-23 A | E3: 2023-24 A | F3: 2024-25 A | G3: 2025-26 E | H3: 2026-27 E | I3: 2027-28 E | J3: 2028-29 E | K3: 2029-30 E
A5: A. CASH FLOW FROM OPERATING ACTIVITIES
A6: Profit Before Tax | C6: 20441.24 | D6: 24807.77 | E6: 27078.57 | F6: 27607.1 | G6: =IS!G17 -> 33929.556 | H6: =IS!H17 -> 36305.238 | I6: =IS!I17 -> 43167.5 | J6: =IS!J17 -> 56262.862 | K6: =IS!K17 -> 66307.142
A7: Adjustments for:
A8: Depreciation and amortisation expense | C8: 1310.1 | D8: 2081.95 | E8: 3618.18 | F8: 5821.08 | G8: =IS!G12 -> 7974.5866 | H8: =IS!H12 -> 10738.498 | I8: =IS!I12 -> 13602.852 | J8: =IS!J12 -> 14395.803 | K8: =IS!K12 -> 15254.25
A9: Allowance for expected credit loss / provision for doubtful advances | C9: -29.75 | D9: 498.74 | E9: 11.28 | F9: -457.96 | G9: 0 | H9: 0 | I9: 0 | J9: 0 | K9: 0
A10: Finance costs | C10: 451.94 | D10: 571.48 | E10: 324.2 | F10: 574.15 | G10: =IS!G14 -> 153.11296 | H10: =IS!H14 -> 144.20856 | I10: =IS!I14 -> 137.96847 | J10: =IS!J14 -> 133.5955 | K10: =IS!K14 -> 130.53098
A11: Liabilities/Provisions no longer required written back | C11: -28.89 | D11: -2823.59 | E11: -4192.26 | F11: -370.85 | G11: 0 | H11: 0 | I11: 0 | J11: 0 | K11: 0
A12: Intangible assets under development written off | C12: 0 | D12: 0 | E12: 267.43 | F12: 0 | G12: 0 | H12: 0 | I12: 0 | J12: 0 | K12: 0
A13: Interest income | C13: -1840.51 | D13: -2950.35 | E13: -4089.65 | F13: -4188.83 | G13: =-IS!G16 -> -4982.564 | H13: =-IS!H16 -> -5813.4197 | I13: =-IS!I16 -> -7185.4836 | J13: =-IS!J16 -> -10523.207 | K13: =-IS!K16 -> -14279.788
A14: Share based payment expense | C14: 75.7 | D14: 306.75 | E14: 965.76 | F14: 469.07 | G14: 0 | H14: 0 | I14: 0 | J14: 0 | K14: 0
A15: Bad debts/advances written off | C15: 0.69 | D15: 4.21 | E15: 725.81 | F15: 207.22 | G15: 0 | H15: 0 | I15: 0 | J15: 0 | K15: 0
A16: Loss on disposal of Property, plant and equipment | C16: 0 | D16: 0 | E16: 1.88 | F16: 0 | G16: 0 | H16: 0 | I16: 0 | J16: 0 | K16: 0
A17: Profit on sale of Property, plant and equipment | C17: 0 | D17: 0 | E17: 0 | F17: -1.93 | G17: 0 | H17: 0 | I17: 0 | J17: 0 | K17: 0
A18: Profit on sale of Investment in Mutual Fund | C18: -48.3 | D18: -1439.27 | E18: -2134.99 | F18: -1305.82 | G18: 0 | H18: 0 | I18: 0 | J18: 0 | K18: 0
A19: Fair value gain on Mutual fund at FVTPL | C19: -555.76 | D19: -564.69 | E19: 505.31 | F19: -90.34 | G19: 0 | H19: 0 | I19: 0 | J19: 0 | K19: 0
A20: Net Loss on foreign currency transactions/translation | C20: -31.35 | D20: -1.39 | E20: 0.26 | F20: 13.83 | G20: 0 | H20: 0 | I20: 0 | J20: 0 | K20: 0
A21: Exceptional Item | C21: 0 | D21: 0 | E21: 0 | F21: -496.21 | G21: 0 | H21: 0 | I21: 0 | J21: 0 | K21: 0
A22: Dividend income from equity investments designated at FVOCI | C22: -695.29 | D22: 0 | E22: 0 | F22: 0 | G22: 0 | H22: 0 | I22: 0 | J22: 0 | K22: 0
A23: Operating profit before Working Capital Changes | C23: =SUM(C6,C8:C22) -> 19049.82 | D23: =SUM(D6,D8:D22) -> 20491.61 | E23: =SUM(E6,E8:E22) -> 23081.78 | F23: =SUM(F6,F8:F22) -> 27780.51 | G23: =SUM(G6,G8:G22) -> 37074.691 | H23: =SUM(H6,H8:H22) -> 41374.525 | I23: =SUM(I6,I8:I22) -> 49722.838 | J23: =SUM(J6,J8:J22) -> 60269.054 | K23: =SUM(K6,K8:K22) -> 67412.135
A24: Changes in working capital
A25: Decrease in Other current assets, Loans, Other non-current assets, Investments, other financial asset | C25: -4839.15 | D25: -1488.68 | E25: 408.36 | F25: 676.86 | G25: =('Balance Sheet'!F24-'Balance Sheet'!G24)+('Balance Sheet'!F21-'Balance Sheet'!G21)+('Balance Sheet'!F17-'Balance Sheet'!G17)+('Balance Sheet'!F22-'Balance Sheet'!G22) -> 0 | H25: =('Balance Sheet'!G24-'Balance Sheet'!H24)+('Balance Sheet'!G21-'Balance Sheet'!H21)+('Balance Sheet'!G17-'Balance Sheet'!H17)+('Balance Sheet'!G22-'Balance Sheet'!H22) -> 0 | I25: =('Balance Sheet'!H24-'Balance Sheet'!I24)+('Balance Sheet'!H21-'Balance Sheet'!I21)+('Balance Sheet'!H17-'Balance Sheet'!I17)+('Balance Sheet'!H22-'Balance Sheet'!I22) -> 0 | J25: =('Balance Sheet'!I24-'Balance Sheet'!J24)+('Balance Sheet'!I21-'Balance Sheet'!J21)+('Balance Sheet'!I17-'Balance Sheet'!J17)+('Balance Sheet'!I22-'Balance Sheet'!J22) -> 0 | K25: =('Balance Sheet'!J24-'Balance Sheet'!K24)+('Balance Sheet'!J21-'Balance Sheet'!K21)+('Balance Sheet'!J17-'Balance Sheet'!K17)+('Balance Sheet'!J22-'Balance Sheet'!K22) -> 0
A26: Increase / (Decrease) in Other financial liabilities, Provisions, Other current liabilities | C26: 5763.86 | D26: 7829.15 | E26: -3670.29 | F26: 7635.82 | G26: =('Balance Sheet'!G48-'Balance Sheet'!F48)+('Balance Sheet'!G49-'Balance Sheet'!F49)+('Balance Sheet'!G50-'Balance Sheet'!F50) -> 0 | H26: =('Balance Sheet'!H48-'Balance Sheet'!G48)+('Balance Sheet'!H49-'Balance Sheet'!G49)+('Balance Sheet'!H50-'Balance Sheet'!G50) -> 0 | I26: =('Balance Sheet'!I48-'Balance Sheet'!H48)+('Balance Sheet'!I49-'Balance Sheet'!H49)+('Balance Sheet'!I50-'Balance Sheet'!H50) -> 0 | J26: =('Balance Sheet'!J48-'Balance Sheet'!I48)+('Balance Sheet'!J49-'Balance Sheet'!I49)+('Balance Sheet'!J50-'Balance Sheet'!I50) -> 0 | K26: =('Balance Sheet'!K48-'Balance Sheet'!J48)+('Balance Sheet'!K49-'Balance Sheet'!J49)+('Balance Sheet'!K50-'Balance Sheet'!J50) -> 0
A27: Increase in Trade payables | C27: 821.99 | D27: 519.73 | E27: 501.85 | F27: 3392.77 | G27: ='Balance Sheet'!G47-'Balance Sheet'!F47 -> -316.76269 | H27: ='Balance Sheet'!H47-'Balance Sheet'!G47 -> 2606.9462 | I27: ='Balance Sheet'!I47-'Balance Sheet'!H47 -> 557.37971 | J27: ='Balance Sheet'!J47-'Balance Sheet'!I47 -> 871.63758 | K27: ='Balance Sheet'!K47-'Balance Sheet'!J47 -> 1962.1602
A28: Decrease in Trade receivables | C28: -2002.44 | D28: -5002.72 | E28: 403.99 | F28: 1792.59 | G28: ='Balance Sheet'!F18-'Balance Sheet'!G18 -> -6477.373 | H28: ='Balance Sheet'!G18-'Balance Sheet'!H18 -> -2352.8103 | I28: ='Balance Sheet'!H18-'Balance Sheet'!I18 -> -3121.0993 | J28: ='Balance Sheet'!I18-'Balance Sheet'!J18 -> -3969.3728 | K28: ='Balance Sheet'!J18-'Balance Sheet'!K18 -> -4937.8157
A29: (Increase) in Inventories | C29: -3624.52 | D29: -6325.53 | E29: -6261.13 | F29: -95.65 | G29: ='Balance Sheet'!F16-'Balance Sheet'!G16 -> 8961.766 | H29: ='Balance Sheet'!G16-'Balance Sheet'!H16 -> -2019.4358 | I29: ='Balance Sheet'!H16-'Balance Sheet'!I16 -> -2684.9685 | J29: ='Balance Sheet'!I16-'Balance Sheet'!J16 -> -3420.3473 | K29: ='Balance Sheet'!J16-'Balance Sheet'!K16 -> -4263.7089
A30: Income taxes paid (net of refund) | C30: -5716.68 | D30: -6680.53 | E30: -5140.02 | F30: -8063.34 | G30: =-IS!G18 -> -8804.0365 | H30: =-IS!H18 -> -9420.4782 | I30: =-IS!I18 -> -11201.097 | J30: =-IS!J18 -> -14599.08 | K30: =-IS!K18 -> -17205.368
A31: Net cash generated from Operating Activities | C31: 9442.52 | D31: =SUM(D23,D25:D30) -> 9343.03 | E31: =SUM(E23,E25:E30) -> 9324.54 | F31: =SUM(F23,F25:F30) -> 33119.56 | G31: =SUM(G23,G25:G30) -> 30438.285 | H31: =SUM(H23,H25:H30) -> 30188.747 | I31: =SUM(I23,I25:I30) -> 33273.052 | J31: =SUM(J23,J25:J30) -> 39151.891 | K31: =SUM(K23,K25:K30) -> 42967.403
A33: B. CASH FLOW FROM INVESTING ACTIVITIES
A34: Purchase of Property, plant and equipment and intangible assets | C34: -7271.33 | D34: -10314.49 | E34: -9227.49 | F34: -16166.33 | G34: =-'Capex Schedule '!G334 -> -28452.179 | H34: =-'Capex Schedule '!H334 -> -28400.991 | I34: =-'Capex Schedule '!I334 -> -28293.097 | J34: =-'Capex Schedule '!J334 -> -8126.0611 | K34: =-'Capex Schedule '!K334 -> -8724.6694
A35: Sale of Property, plant and equipment | C35: 0 | D35: 0 | E35: 0 | F35: 10.73 | G35: 0 | H35: 0 | I35: 0 | J35: 0 | K35: 0
A36: Consideration paid for business combination | C36: 0 | D36: 0 | E36: -16618.92 | F36: -12747.12 | G36: 0 | H36: 0 | I36: 0 | J36: 0 | K36: 0
A37: Interest received | C37: 677.98 | D37: 1390.25 | E37: 5680.4 | F37: 4341.31 | G37: =IS!G16 -> 4982.564 | H37: =IS!H16 -> 5813.4197 | I37: =IS!I16 -> 7185.4836 | J37: =IS!J16 -> 10523.207 | K37: =IS!K16 -> 14279.788
A38: Investment in Mutual funds | C38: -61310.45 | D38: -39013.58 | E38: -22529.33 | F38: -31894.9 | G38: 0 | H38: 0 | I38: 0 | J38: 0 | K38: 0
A39: Fixed deposits (placed)/matured with banks (with maturity more than 3 months) | C39: -7175.29 | D39: -37092.89 | E39: 7605.28 | F39: 453.41 | G39: 0 | H39: 0 | I39: 0 | J39: 0 | K39: 0
A40: Proceeds from sale of Investment in Mutual funds | C40: 11354.53 | D40: 70216.46 | E40: 36749.48 | F40: 33942.7 | G40: 0 | H40: 0 | I40: 0 | J40: 0 | K40: 0
A41: Net cash used in Investing Activities | C41: -63029.27 | D41: =SUM(D34:D40) -> -14814.25 | E41: =SUM(E34:E40) -> 1659.42 | F41: =SUM(F34:F40) -> -22060.2 | G41: =SUM(G34:G40) -> -23469.615 | H41: =SUM(H34:H40) -> -22587.572 | I41: =SUM(I34:I40) -> -21107.614 | J41: =SUM(J34:J40) -> 2397.1459 | K41: =SUM(K34:K40) -> 5555.1186
A43: C. CASH FLOW FROM FINANCING ACTIVITIES
...

Sheet Revenue Model
A1: Revene Model
A2: Figures in Lakhs ,expect otherwise stated
A3: Particular/Years | B3: Comments | C3: 2021-22 A | D3: 2022-23 A | E3: 2023-24 A | F3: 2024-25 A | G3: 2025-26 E | H3: 2026-27 E | I3: 2027-28 E | J3: 2028-29 E | K3: 2029-30 E
A5: =IS!A4 -> Revenue from operations | C5: =IS!C4 -> 58062.76 | D5: =IS!D4 -> 73662.12 | E5: =IS!E4 -> 80300.4 | F5: =IS!F4 -> 117135.76 | G5: =SUM(G8:G14) -> 126526.54 | H5: =SUM(H8:H14) -> 140839.47 | I5: =SUM(I8:I14) -> 159826.15 | J5: =SUM(J8:J14) -> 183973.17 | K5: =SUM(K8:K14) -> 214011.55
A7: Segment Wise Revenue Breakup
A8: Sale of product | B8: Carvaan and others | C8: 10167.72 | D8: 12760.93 | E8: 12962 | F8: 8154.52 | G8: =G18 -> 5218.8928 | H8: =H18 -> 3340.0914 | I8: =I18 -> 2137.6585 | J8: =J18 -> 1368.1014 | K8: =K18 -> 875.58492
A9: Sale of service-
A10: License Fees- Music | C10: 36328.85 | D10: 42122.5 | E10: 47828.58 | F10: 53860.92 | G10: =G26 -> 64308.4 | H10: =H26 -> 79353.293 | I10: =I26 -> 91176.806 | J10: =J26 -> 103721.92 | K10: =K26 -> 118674.53
A11: Artist Management | C11: 0 | D11: 0 | E11: 2075.82 | F11: 6931.24 | G11: =G77 -> 9250.114 | H11: =H77 -> 9652.508 | I11: =I77 -> 16520.213 | J11: =J77 -> 26591.471 | K11: =K77 -> 39004.672
A12: Income from videos | B12: Films, Tv and digital content | C12: 10239.13 | D12: 10846.29 | E12: 11586.66 | F12: 19197.76 | G12: =G82 -> 22077.424 | H12: =H82 -> 25389.038 | I12: =I82 -> 29197.393 | J12: =J82 -> 33577.002 | K12: =K82 -> 38613.553
A13: Income from events | C13: 0 | D13: 4895.66 | E13: 1344.17 | F13: 28524.12 | G13: =G85 -> 25671.708 | H13: =H85 -> 23104.537 | I13: =I85 -> 20794.083 | J13: =J85 -> 18714.675 | K13: =K85 -> 16843.208
A14: Other operating income | B14: Amount written back | C14: =884.21+442.85 -> 1327.06 | D14: 3036.74 | E14: 4503.17 | F14: 467.2 | G14: =G88 -> 0 | H14: =H88 -> 0 | I14: =I88 -> 0 | J14: =J88 -> 0 | K14: =K88 -> 0
A16: Sale of Product-
A18: =A8 -> Sale of product | C18: =C8 -> 10167.72 | D18: =D8 -> 12760.93 | E18: =E8 -> 12962 | F18: =F8 -> 8154.52 | G18: =G19*G20 -> 5218.8928 | H18: =H19*H20 -> 3340.0914 | I18: =I19*I20 -> 2137.6585 | J18: =J19*J20 -> 1368.1014 | K18: =K19*K20 -> 875.58492
A19: Carvaan Sale ( In Lakhs) | C19: 4.01 | D19: 5.61 | E19: 6.86 | F19: 4.34 | G19: =F19*(1+G21) -> 3.472 | H19: =G19*(1+H21) -> 2.7776 | I19: =H19*(1+I21) -> 2.22208 | J19: =I19*(1+J21) -> 1.777664 | K19: =J19*(1+K21) -> 1.4221312
A20: Average Selling Price (In Rs.) | C20: =C8/C19 -> 2535.591 | D20: =D8/D19 -> 2274.6756 | E20: =E8/E19 -> 1889.5044 | F20: =F8/F19 -> 1878.9217 | G20: =F20*(1+G22) -> 1503.1373 | H20: =G20*(1+H22) -> 1202.5099 | I20: =H20*(1+I22) -> 962.00789 | J20: =I20*(1+J22) -> 769.60631 | K20: =J20*(1+K22) -> 615.68505
A21: Y-o-Y Growth in Sale in Quantity of Products | C21: - | D21: =D19/C19-1 -> 0.39900249 | E21: =E19/D19-1 -> 0.2228164 | F21: =F19/E19-1 -> -0.36734694 | G21: ='Assumption Sheet'!G8 -> -0.2 | H21: ='Assumption Sheet'!H8 -> -0.2 | I21: ='Assumption Sheet'!I8 -> -0.2 | J21: ='Assumption Sheet'!J8 -> -0.2 | K21: ='Assumption Sheet'!K8 -> -0.2
A22: Y-o-Y Growth in Average Selling Price of Products | C22: - | D22: =D20/C20-1 -> -0.10290123 | E22: =E20/D20-1 -> -0.16933017 | F22: =F20/E20-1 -> -0.0056007884 | G22: ='Assumption Sheet'!G9 -> -0.2 | H22: ='Assumption Sheet'!H9 -> -0.2 | I22: ='Assumption Sheet'!I9 -> -0.2 | J22: ='Assumption Sheet'!J9 -> -0.2 | K22: ='Assumption Sheet'!K9 -> -0.2
A24: Sale of Service-
A26: =A10 -> License Fees- Music | C26: =C10 -> 36328.85 | D26: =D10 -> 42122.5 | E26: =E10 -> 47828.58 | F26: =F10 -> 53860.92 | G26: =SUM(G36:G40) -> 64308.4 | H26: =SUM(H36:H40) -> 79353.293 | I26: =SUM(I36:I40) -> 91176.806 | J26: =SUM(J36:J40) -> 103721.92 | K26: =SUM(K36:K40) -> 118674.53
A28: Era wise Segment (Revenue in %)
A29: 2021-2024 | C29: 0 | D29: 0.27 | E29: 0.33 | F29: 0.4
A30: 2001-2020 | C30: 0.4 | D30: 0.207 | E30: 0.19 | F30: 0.16
A31: 1981-2000 | C31: 0.26 | D31: 0.207 | E31: 0.2 | F31: 0.18
A32: 1961-1980 | C32: 0.31 | D32: 0.29 | E32: 0.25 | F32: 0.23
A33: Till 1960 | C33: 0.03 | D33: 0.026 | E33: 0.03 | F33: 0.03
A35: Era wise Segment (Revenue in Number in Lakhs )
A36: 2021-2024 | C36: =C29*C$26 -> 0 | D36: =D29*D$26 -> 11373.075 | E36: =E29*E$26 -> 15783.431 | F36: =F29*F$26 -> 21544.368 | G36: =G58*G69 -> 30085.171 | H36: =H58*H69 -> 43110.28 | I36: =I58*I69 -> 52794.166 | J36: =J58*J69 -> 63072.676 | K36: =K58*K69 -> 75624.139
A37: 2001-2020 | C37: =C30*C$26 -> 14531.54 | D37: =D30*D$26 -> 8719.3575 | E37: =E30*E$26 -> 9087.4302 | F37: =F30*F$26 -> 8617.7472 | G37: =F37*(1+G44) -> 9134.812 | H37: =G37*(1+H44) -> 9682.9008 | I37: =H37*(1+I44) -> 10263.875 | J37: =I37*(1+J44) -> 10879.707 | K37: =J37*(1+K44) -> 11532.49
A38: 1981-2000 | C38: =C31*C$26 -> 9445.501 | D38: =D31*D$26 -> 8719.3575 | E38: =E31*E$26 -> 9565.716 | F38: =F31*F$26 -> 9694.9656 | G38: =F38*(1+G45) -> 10276.664 | H38: =G38*(1+H45) -> 10893.263 | I38: =H38*(1+I45) -> 11546.859 | J38: =I38*(1+J45) -> 12239.671 | K38: =J38*(1+K45) -> 12974.051
A39: 1961-1980 | C39: =C32*C$26 -> 11261.943 | D39: =D32*D$26 -> 12215.525 | E39: =E32*E$26 -> 11957.145 | F39: =F32*F$26 -> 12388.012 | G39: =F39*(1+G46) -> 13131.292 | H39: =G39*(1+H46) -> 13919.17 | I39: =H39*(1+I46) -> 14754.32 | J39: =I39*(1+J46) -> 15639.579 | K39: =J39*(1+K46) -> 16577.954
A40: Till 1960 | C40: =C33*C$26 -> 1089.8655 | D40: =D33*D$26 -> 1095.185 | E40: =E33*E$26 -> 1434.8574 | F40: =F33*F$26 -> 1615.8276 | G40: =F40*(1+G47) -> 1680.4607 | H40: =G40*(1+H47) -> 1747.6791 | I40: =H40*(1+I47) -> 1817.5863 | J40: =I40*(1+J47) -> 1890.2897 | K40: =J40*(1+K47) -> 1965.9013
A42: Era wise Segment (YoY Growth in Revenue)
A43: 2021-2024 | C43: - | D43: - | E43: =E36/D36-1 -> 0.38778927 | F43: =F36/E36-1 -> 0.364999
A44: 2001-2020 | C44: - | D44: =D37/C37-1 -> -0.39997017 | E44: =E37/D37-1 -> 0.042213282 | F44: =F37/E37-1 -> -0.051684909 | G44: ='Assumption Sheet'!G13 -> 0.06 | H44: ='Assumption Sheet'!H13 -> 0.06 | I44: ='Assumption Sheet'!I13 -> 0.06 | J44: ='Assumption Sheet'!J13 -> 0.06 | K44: ='Assumption Sheet'!K13 -> 0.06
A45: 1981-2000 | C45: - | D45: =D38/C38-1 -> -0.076877182 | E45: =E38/D38-1 -> 0.097066613 | F45: =F38/E38-1 -> 0.013511754 | G45: ='Assumption Sheet'!G14 -> 0.06 | H45: ='Assumption Sheet'!H14 -> 0.06 | I45: ='Assumption Sheet'!I14 -> 0.06 | J45: ='Assumption Sheet'!J14 -> 0.06 | K45: ='Assumption Sheet'!K14 -> 0.06
A46: 1961-1980 | C46: - | D46: =D39/C39-1 -> 0.084672907 | E46: =E39/D39-1 -> -0.021151772 | F46: =F39/E39-1 -> 0.036034237 | G46: ='Assumption Sheet'!G15 -> 0.06 | H46: ='Assumption Sheet'!H15 -> 0.06 | I46: ='Assumption Sheet'!I15 -> 0.06 | J46: ='Assumption Sheet'!J15 -> 0.06 | K46: ='Assumption Sheet'!K15 -> 0.06
A47: Till 1960 | C47: - | D47: =D40/C40-1 -> 0.0048808775 | E47: =E40/D40-1 -> 0.31015071 | F47: =F40/E40-1 -> 0.12612417 | G47: ='Assumption Sheet'!G16 -> 0.04 | H47: ='Assumption Sheet'!H16 -> 0.04 | I47: ='Assumption Sheet'!I16 -> 0.04 | J47: ='Assumption Sheet'!J16 -> 0.04 | K47: ='Assumption Sheet'!K16 -> 0.04
A49: Era wise Segment (Count in %)
A50: 2021-2024 | C50: 0 | D50: 0.08 | E50: 0.14 | F50: 0.16
...

Sheet Cost Model 
A1: Cost Model
A2: Figures in Lakhs ,expect otherwise stated
A3: Particular/Years | B3: Comments | C3: 2021-22 A | D3: 2022-23 A | E3: 2023-24 A | F3: 2024-25 A | G3: 2025-26 E | H3: 2026-27 E | I3: 2027-28 E | J3: 2028-29 E | K3: 2029-30 E
A5: =IS!A5 -> Cost of Music Business | C5: =IS!C5 -> 6912.28 | D5: =IS!D5 -> 9090.75 | E5: =IS!E5 -> 10693.99 | F5: =IS!F5 -> 8708.41 | G5: =G10*G12 -> 12027.589 | H5: =H10*H12 -> 14099.201 | I5: =I10*I12 -> 16769.356 | J5: =J10*J12 -> 20104.888 | K5: =K10*K12 -> 24207.853
A7: ='Revenue Model'!A8 -> Sale of product | C7: ='Revenue Model'!C8 -> 10167.72 | D7: ='Revenue Model'!D8 -> 12760.93 | E7: ='Revenue Model'!E8 -> 12962 | F7: ='Revenue Model'!F8 -> 8154.52 | G7: ='Revenue Model'!G8 -> 5218.8928 | H7: ='Revenue Model'!H8 -> 3340.0914 | I7: ='Revenue Model'!I8 -> 2137.6585 | J7: ='Revenue Model'!J8 -> 1368.1014 | K7: ='Revenue Model'!K8 -> 875.58492
A8: ='Revenue Model'!A10 -> License Fees- Music | C8: ='Revenue Model'!C10 -> 36328.85 | D8: ='Revenue Model'!D10 -> 42122.5 | E8: ='Revenue Model'!E10 -> 47828.58 | F8: ='Revenue Model'!F10 -> 53860.92 | G8: ='Revenue Model'!G10 -> 64308.4 | H8: ='Revenue Model'!H10 -> 79353.293 | I8: ='Revenue Model'!I10 -> 91176.806 | J8: ='Revenue Model'!J10 -> 103721.92 | K8: ='Revenue Model'!K10 -> 118674.53
A9: ='Revenue Model'!A11 -> Artist Management | C9: ='Revenue Model'!C11 -> 0 | D9: ='Revenue Model'!D11 -> 0 | E9: ='Revenue Model'!E11 -> 2075.82 | F9: ='Revenue Model'!F11 -> 6931.24 | G9: ='Revenue Model'!G11 -> 9250.114 | H9: ='Revenue Model'!H11 -> 9652.508 | I9: ='Revenue Model'!I11 -> 16520.213 | J9: ='Revenue Model'!J11 -> 26591.471 | K9: ='Revenue Model'!K11 -> 39004.672
A10: Total Income from Music | C10: =SUM(C7:C9) -> 46496.57 | D10: =SUM(D7:D9) -> 54883.43 | E10: =SUM(E7:E9) -> 62866.4 | F10: =SUM(F7:F9) -> 68946.68 | G10: =SUM(G7:G9) -> 78777.406 | H10: =SUM(H7:H9) -> 92345.893 | I10: =SUM(I7:I9) -> 109834.68 | J10: =SUM(J7:J9) -> 131681.5 | K10: =SUM(K7:K9) -> 158554.79
A12: Cost of music/Income from music | C12: =C5/C10 -> 0.14866215 | D12: =D5/D10 -> 0.16563742 | E12: =E5/E10 -> 0.17010661 | F12: =F5/F10 -> 0.12630644 | G12: ='Assumption Sheet'!G40 -> 0.15267816 | H12: ='Assumption Sheet'!H40 -> 0.15267816 | I12: ='Assumption Sheet'!I40 -> 0.15267816 | J12: ='Assumption Sheet'!J40 -> 0.15267816 | K12: ='Assumption Sheet'!K40 -> 0.15267816
A15: =IS!A6 -> Cost of Films, Tv serials and Digital content (under production and untelecasted) | C15: =IS!C6 -> 7398.35 | D15: =IS!D6 -> 13413.68 | E15: =IS!E6 -> 12510.53 | F15: =IS!F6 -> 45600.27 | G15: =G19*G21 -> 38199.306 | H15: =H19*H21 -> 38794.86 | I15: =I19*I21 -> 37493.608 | J15: =J19*J21 -> 36604.174 | K15: =K19*K21 -> 38819.732
A17: ='Revenue Model'!A12 -> Income from videos | C17: ='Revenue Model'!C12 -> 10239.13 | D17: ='Revenue Model'!D12 -> 10846.29 | E17: ='Revenue Model'!E12 -> 11586.66 | F17: ='Revenue Model'!F12 -> 19197.76 | G17: ='Revenue Model'!G12 -> 22077.424 | H17: ='Revenue Model'!H12 -> 25389.038 | I17: ='Revenue Model'!I12 -> 29197.393 | J17: ='Revenue Model'!J12 -> 33577.002 | K17: ='Revenue Model'!K12 -> 38613.553
A18: ='Revenue Model'!A13 -> Income from events | C18: ='Revenue Model'!C13 -> 0 | D18: ='Revenue Model'!D13 -> 4895.66 | E18: ='Revenue Model'!E13 -> 1344.17 | F18: ='Revenue Model'!F13 -> 28524.12 | G18: ='Revenue Model'!G13 -> 25671.708 | H18: ='Revenue Model'!H13 -> 23104.537 | I18: ='Revenue Model'!I13 -> 20794.083 | J18: ='Revenue Model'!J13 -> 18714.675 | K18: ='Revenue Model'!K13 -> 16843.208
A19: Total Income from Films and events | C19: =SUM(C17:C18) -> 10239.13 | D19: =SUM(D17:D18) -> 15741.95 | E19: =SUM(E17:E18) -> 12930.83 | F19: =SUM(F17:F18) -> 47721.88 | G19: =SUM(G17:G18) -> 47749.132 | H19: =SUM(H17:H18) -> 48493.575 | I19: =SUM(I17:I18) -> 49991.477 | J19: =SUM(J17:J18) -> 52291.677 | K19: =SUM(K17:K18) -> 55456.76
A21: Cost of films and events/Income from films and events | C21: =C15/C19 -> 0.72255651 | D21: =D15/D19 -> 0.85209774 | E21: =E15/E19 -> 0.96749629 | F21: =F15/F19 -> 0.9555422 | G21: ='Assumption Sheet'!G43 -> 0.8 | H21: ='Assumption Sheet'!H43 -> 0.8 | I21: ='Assumption Sheet'!I43 -> 0.75 | J21: ='Assumption Sheet'!J43 -> 0.7 | K21: ='Assumption Sheet'!K43 -> 0.7
A24: =IS!A7 -> Employee benefits expense | C24: =IS!C7 -> 7344.7 | D24: =IS!D7 -> 7499.89 | E24: =IS!E7 -> 9316.06 | F24: =IS!F7 -> 10749.67 | G24: =(G26*G27)+(G30*G31)+(G34*G35) -> 8073.2067 | H24: =(H26*H27)+(H30*H31)+(H34*H35) -> 11308.212 | I24: =(I26*I27)+(I30*I31)+(I34*I35) -> 15785.883 | J24: =(J26*J27)+(J30*J31)+(J34*J35) -> 21978.012 | K24: =(K26*K27)+(K30*K31)+(K34*K35) -> 30431.48
A26: No. of BOD | D26: 8 | E26: 7 | F26: 8 | G26: ='Assumption Sheet'!G46 -> 8 | H26: ='Assumption Sheet'!H46 -> 8 | I26: ='Assumption Sheet'!I46 -> 8 | J26: ='Assumption Sheet'!J46 -> 8 | K26: ='Assumption Sheet'!K46 -> 8
A27: Median Salary BOD | C27: - | D27: - | E27: =AVERAGE(2.95,1.1) -> 2.025 | F27: =AVERAGE(5.15,2) -> 3.575 | G27: =F27*(1+G28) -> 4.9432099 | H27: =G27*(1+H28) -> 6.8350556 | I27: =H27*(1+I28) -> 9.4509411 | J27: =I27*(1+J28) -> 13.067968 | K27: =J27*(1+K28) -> 18.069289
A28: YoY Increase in Median Salary of BOD | C28: - | D28: - | E28: 0 | F28: =F27/E27-1 -> 0.7654321 | G28: ='Assumption Sheet'!G47 -> 0.38271605 | H28: ='Assumption Sheet'!H47 -> 0.38271605 | I28: ='Assumption Sheet'!I47 -> 0.38271605 | J28: ='Assumption Sheet'!J47 -> 0.38271605 | K28: ='Assumption Sheet'!K47 -> 0.38271605
A30: No. of KMP (Key Managerial Personell) | C30: 3 | D30: 3 | E30: 3 | F30: 3 | G30: ='Assumption Sheet'!G49 -> 3 | H30: ='Assumption Sheet'!H49 -> 3 | I30: ='Assumption Sheet'!I49 -> 3 | J30: ='Assumption Sheet'!J49 -> 3 | K30: ='Assumption Sheet'!K49 -> 3
A31: Median Salary KMP | C31: =MEDIAN(937.83,201.13,16.65) -> 201.13 | D31: =AVERAGE(587.02,7.32) -> 297.17 | E31: =AVERAGE(698.79,12.56) -> 355.675 | F31: =AVERAGE(832.02,14.47) -> 423.245 | G31: =F31*(1+G32) -> 545.18933 | H31: =G31*(1+H32) -> 667.85115 | I31: =H31*(1+I32) -> 824.3696 | J31: =I31*(1+J32) -> 1029.7663 | K31: =J31*(1+K32) -> 1272.9651
A32: YoY Increase in Median Salary of BOD | C32: - | D32: =D31/C31-1 -> 0.47750211 | E32: =E31/D31-1 -> 0.19687384 | F32: =F31/E31-1 -> 0.1899768 | G32: ='Assumption Sheet'!G50 -> 0.28811759 | H32: ='Assumption Sheet'!H50 -> 0.22498941 | I32: ='Assumption Sheet'!I50 -> 0.23436127 | J32: ='Assumption Sheet'!J50 -> 0.24915609 | K32: ='Assumption Sheet'!K50 -> 0.23616892
A34: Total Number of Employees (Other than BOD and KMP) | B34: Permanent + Other than permanent | C34: 407 | D34: 372 | E34: 454 | F34: 396 | G34: =F34+'Assumption Sheet'!G53 -> 446 | H34: =G34+'Assumption Sheet'!H53 -> 496 | I34: =H34+'Assumption Sheet'!I53 -> 546 | J34: =I34+'Assumption Sheet'!J53 -> 596 | K34: =J34+'Assumption Sheet'!K53 -> 646
A35: Median Salary Employee | D35: =AVERAGE(9.5,9.5) -> 9.5 | E35: =AVERAGE(10.19,8) -> 9.095 | F35: =AVERAGE(12.08,9.99) -> 11.035 | G35: =F35*(1+G36) -> 14.3455 | H35: =G35*(1+H36) -> 18.64915 | I35: =H35*(1+I36) -> 24.243895 | J35: =I35*(1+J36) -> 31.517064 | K35: =J35*(1+K36) -> 40.972183
A36: YoY Increase in Median Salary of Employee (Other than BOD and KMP) | C36: - | D36: - | E36: =E35/D35-1 -> -0.042631579 | F36: =F35/E35-1 -> 0.21330401 | G36: ='Assumption Sheet'!G54 -> 0.3 | H36: ='Assumption Sheet'!H54 -> 0.3 | I36: ='Assumption Sheet'!I54 -> 0.3 | J36: ='Assumption Sheet'!J54 -> 0.3 | K36: ='Assumption Sheet'!K54 -> 0.3
A39: =IS!A8 -> Royalty expenses | C39: =IS!C8 -> 6313.76 | D39: =IS!D8 -> 6555.33 | E39: =IS!E8 -> 6126.64 | F39: =IS!F8 -> 6831.37 | G39: =G40*G41 -> 7073.924 | H39: =H40*H41 -> 8728.8623 | I39: =I40*I41 -> 10029.449 | J39: =J40*J41 -> 11409.412 | K39: =K40*K41 -> 13054.199
A40: ='Revenue Model'!A26 -> License Fees- Music | C40: ='Revenue Model'!C26 -> 36328.85 | D40: ='Revenue Model'!D26 -> 42122.5 | E40: ='Revenue Model'!E26 -> 47828.58 | F40: ='Revenue Model'!F26 -> 53860.92 | G40: ='Revenue Model'!G26 -> 64308.4 | H40: ='Revenue Model'!H26 -> 79353.293 | I40: ='Revenue Model'!I26 -> 91176.806 | J40: ='Revenue Model'!J26 -> 103721.92 | K40: ='Revenue Model'!K26 -> 118674.53
A41: Royalty Expense / License Income | C41: =C39/C40 -> 0.17379466 | D41: =D39/D40 -> 0.15562538 | E41: =E39/E40 -> 0.1280958 | F41: =F39/F40 -> 0.12683352 | G41: ='Assumption Sheet'!G57 -> 0.11 | H41: ='Assumption Sheet'!H57 -> 0.11 | I41: ='Assumption Sheet'!I57 -> 0.11 | J41: ='Assumption Sheet'!J57 -> 0.11 | K41: ='Assumption Sheet'!K57 -> 0.11
A44: =IS!A9 -> Advertisement and sales promotion | C44: =IS!C9 -> 5205.33 | D44: =IS!D9 -> 7710.99 | E44: =IS!E9 -> 7598.01 | F44: =IS!F9 -> 9041.17 | G44: =G45*G46 -> 11581.474 | H44: =H45*H46 -> 12891.593 | I44: =I45*I46 -> 14629.52 | J44: =J45*J46 -> 16839.792 | K44: =K45*K46 -> 19589.324
A45: =IS!A4 -> Revenue from operations | C45: =IS!C4 -> 58062.76 | D45: =IS!D4 -> 73662.12 | E45: =IS!E4 -> 80300.4 | F45: =IS!F4 -> 117135.76 | G45: =IS!G4 -> 126526.54 | H45: =IS!H4 -> 140839.47 | I45: =IS!I4 -> 159826.15 | J45: =IS!J4 -> 183973.17 | K45: =IS!K4 -> 214011.55
